Workbook

Sheet Core HTMLCSS
C1: Marks 0 — has no idea about the topic 1 — has some theoretical knowledge and can do simple tasks and understand code samples 2 — can do normal tasks without being constantly supervised 3 — has appropriate experience and can perform the majority of real-life tasks 4 — has deep understanding, knows underwater stones, can mentor and educate
C2: Legend : | D2: 0.09 | E2: 0.9 | F2: Lesser important | H2: Min score | J2: Result
D3: 0.91 | E3: 1.2 | F3: Important | J3: =IF(J4>=$H$4,1,0) -> 1 | K3: =IF(K4>=$H$4,1,0) -> 0
C4: Version 0.11.0 | D4: 1.21 | E4: 2 | F4: Very important | H4: 0.75 | J4: =SUMPRODUCT(J$9:J541,$B$9:$B541,OFFSET(INDIRECT(CONCATENATE("R8C",IF($J$6="FE",3,9)+J$8),FALSE),1,0,533,1))/SUMPRODUCT($B$9:$B541,OFFSET(INDIRECT(CONCATENATE("R8C",IF($J$6="FE",3,9)+J$8),FALSE),1,0,533,1)) -> 0.95797721 | K4: =SUMPRODUCT(K$9:K541,$B$9:$B541,OFFSET(INDIRECT(CONCATENATE("R8C",IF($J$6="FE",3,9)+K$8),FALSE),1,0,533,1))/SUMPRODUCT($B$9:$B541,OFFSET(INDIRECT(CONCATENATE("R8C",IF($J$6="FE",3,9)+K$8),FALSE),1,0,533,1)) -> 0
C6: 'Core HTML / CSS' - evaluation matrix | D6: UX developer | J6: FE
D7: Level | J7: 2020-Q2 | M7: <- assessment date
D8: 1 | E8: 2 | F8: 3 | G8: 4 | H8: 5 | J8: 1 | K8: 2 | M8: <- assessment levels
B9: =IF(EXACT(A9,"+"),1,0) -> 0 | C9: HTML + CSS (layout coding)
A10: + | B10: =IF(EXACT(A10,"+"),1,0) -> 1 | C10: Basic | D10: 1.8 | E10: 1.5 | F10: 0.8 | G10: 0.8 | H10: 0.8 | J10: =IF(COUNTA(OFFSET(J11,0,0,MATCH("+",$A11:$A$502,-1)-1,1)), COUNTIF(OFFSET(J11,0,0,MATCH("+",$A11:$A$502,-1)-1,1),">=1")/COUNTA(OFFSET(J11,0,0,MATCH("+",$A11:$A$502,-1)-1,1)), 0) -> 1 | K10: =IF(COUNTA(OFFSET(K11,0,0,MATCH("+",$A11:$A$502,-1)-1,1)), COUNTIF(OFFSET(K11,0,0,MATCH("+",$A11:$A$502,-1)-1,1),">=1")/COUNTA(OFFSET(K11,0,0,MATCH("+",$A11:$A$502,-1)-1,1)), 0) -> 0
B11: =IF(EXACT(A11,"+"),1,0) -> 0 | C11: Basic HTML Page Structure | D11: 2 | E11: 3 | F11: 4 | G11: 4 | H11: 4 | J11: 3 | M11: <- skill check result
B12: =IF(EXACT(A12,"+"),1,0) -> 0 | C12: Document Type Definition, HTML, XHTML | D12: 2 | E12: 3 | F12: 4 | G12: 4 | H12: 4 | J12: 3
B13: =IF(EXACT(A13,"+"),1,0) -> 0 | C13: Metadata, Styles, Scripts | D13: 2 | E13: 3 | F13: 4 | G13: 4 | H13: 4 | J13: 3
B14: =IF(EXACT(A14,"+"),1,0) -> 0 | C14: Text Formatting Tags And CSS Text Formatting | D14: 2 | E14: 3 | F14: 4 | G14: 4 | H14: 4 | J14: 3
B15: =IF(EXACT(A15,"+"),1,0) -> 0 | C15: Table | D15: 2 | E15: 3 | F15: 4 | G15: 4 | H15: 4 | J15: 3
B16: 0 | C16: Form, Input Tags | D16: 2 | E16: 3 | F16: 4 | G16: 4 | H16: 4 | J16: 3
B17: =IF(EXACT(A17,"+"),1,0) -> 0 | C17: CSS Rules, Selectors | D17: 2 | E17: 3 | F17: 4 | G17: 4 | H17: 4 | J17: 3
B18: =IF(EXACT(A18,"+"),1,0) -> 0 | C18: CSS Decoration (border, background, text-decoration, text-transform) | D18: 2 | E18: 3 | F18: 4 | G18: 4 | H18: 4 | J18: 3
B19: 0 | C19: Box and Text Shadow | D19: 1 | E19: 2 | F19: 3 | G19: 3 | H19: 4 | J19: 2
B20: =IF(EXACT(A20,"+"),1,0) -> 0 | C20: CSS Units | D20: 2 | E20: 3 | F20: 4 | G20: 4 | H20: 4 | J20: 3
A21: + | B21: =IF(EXACT(A21,"+"),1,0) -> 1 | C21: Intermediate | D21: 1.2 | E21: 1.8 | F21: 1.5 | G21: 1 | H21: 1 | J21: =IF(COUNTA(OFFSET(J22,0,0,MATCH("+",$A22:$A$502,-1)-1,1)), COUNTIF(OFFSET(J22,0,0,MATCH("+",$A22:$A$502,-1)-1,1),">=1")/COUNTA(OFFSET(J22,0,0,MATCH("+",$A22:$A$502,-1)-1,1)), 0) -> 1 | K21: =IF(COUNTA(OFFSET(K22,0,0,MATCH("+",$A22:$A$502,-1)-1,1)), COUNTIF(OFFSET(K22,0,0,MATCH("+",$A22:$A$502,-1)-1,1),">=1")/COUNTA(OFFSET(K22,0,0,MATCH("+",$A22:$A$502,-1)-1,1)), 0) -> 0
B22: =IF(EXACT(A22,"+"),1,0) -> 0 | C22: HTML5 Tags | D22: 1 | E22: 2 | F22: 3 | G22: 4 | H22: 4 | J22: 2
B23: =IF(EXACT(A23,"+"),1,0) -> 0 | C23: HTML5 Input Tags | D23: 1 | E23: 2 | F23: 3 | G23: 4 | H23: 4 | J23: 2
B24: =IF(EXACT(A24,"+"),1,0) -> 0 | C24: CSS Standart And Box Model | D24: 2 | E24: 3 | F24: 4 | G24: 4 | H24: 4 | J24: 3
B25: =IF(EXACT(A25,"+"),1,0) -> 0 | C25: Positioning | D25: 2 | E25: 3 | F25: 4 | G25: 4 | H25: 4 | J25: 2
B26: =IF(EXACT(A26,"+"),1,0) -> 0 | C26: Markup Layout | D26: 1 | E26: 2 | F26: 3 | G26: 4 | H26: 4 | J26: 2
B27: =IF(EXACT(A27,"+"),1,0) -> 0 | C27: Display | D27: 2 | E27: 3 | F27: 4 | G27: 4 | H27: 4 | J27: 2
B28: =IF(EXACT(A28,"+"),1,0) -> 0 | C28: Pseudo-classes (:first-child, :last-child, etc) | D28: 1 | E28: 2 | F28: 3 | G28: 4 | H28: 4 | J28: 2
B29: =IF(EXACT(A29,"+"),1,0) -> 0 | C29: Pseudo-elements (::before, ::after, etc) | D29: 1 | E29: 2 | F29: 3 | G29: 4 | H29: 4 | J29: 2
B30: =IF(EXACT(A30,"+"),1,0) -> 0 | C30: Cascading and Inheritance | D30: 1 | E30: 2 | F30: 3 | G30: 4 | H30: 4 | J30: 2
B31: =IF(EXACT(A31,"+"),1,0) -> 0 | C31: Fonts (system fonts, @font-face) | D31: 1 | E31: 2 | F31: 3 | G31: 4 | H31: 4 | J31: 2
B32: =IF(EXACT(A32,"+"),1,0) -> 0 | C32: Opacity | D32: 1 | E32: 2 | F32: 3 | G32: 4 | H32: 4 | J32: 2
A33: + | B33: =IF(EXACT(A33,"+"),1,0) -> 1 | C33: Advanced | D33: 0.8 | E33: 1.2 | F33: 1.5 | G33: 1.5 | H33: 1 | J33: =IF(COUNTA(OFFSET(J34,0,0,MATCH("+",$A34:$A$502,-1)-1,1)), COUNTIF(OFFSET(J34,0,0,MATCH("+",$A34:$A$502,-1)-1,1),">=1")/COUNTA(OFFSET(J34,0,0,MATCH("+",$A34:$A$502,-1)-1,1)), 0) -> 0.88888889 | K33: =IF(COUNTA(OFFSET(K34,0,0,MATCH("+",$A34:$A$502,-1)-1,1)), COUNTIF(OFFSET(K34,0,0,MATCH("+",$A34:$A$502,-1)-1,1),">=1")/COUNTA(OFFSET(K34,0,0,MATCH("+",$A34:$A$502,-1)-1,1)), 0) -> 0
B34: =IF(EXACT(A34,"+"),1,0) -> 0 | C34: Attribute selectors (^=, *=, etc) | D34: 1 | E34: 2 | F34: 3 | G34: 4 | H34: 4 | J34: 1
B35: =IF(EXACT(A35,"+"),1,0) -> 0 | C35: CSS3 transform, transition, animation, resize | D35: 0 | E35: 1 | F35: 2 | G35: 4 | H35: 4 | J35: 1
B36: =IF(EXACT(A36,"+"),1,0) -> 0 | C36: Flexible Box Model | D36: 0 | E36: 1 | F36: 2 | G36: 4 | H36: 4 | J36: 1
B37: =IF(EXACT(A37,"+"),1,0) -> 0 | C37: Media-queries | D37: 1 | E37: 2 | F37: 3 | G37: 4 | H37: 4 | J37: 2
B38: =IF(EXACT(A38,"+"),1,0) -> 0 | C38: Responsive design | D38: 1 | E38: 2 | F38: 3 | G38: 4 | H38: 4 | J38: 2
B39: 0 | C39: Viewport | D39: 1 | E39: 2 | F39: 3 | G39: 4 | H39: 4 | J39: 2
B40: 0 | C40: Less, Sass, Stylus | D40: 1 | E40: 2 | F40: 3 | G40: 3 | H40: 4 | J40: 2
B41: 0 | C41: Accessibility | D41: 0 | E41: 1 | F41: 2 | G41: 3 | H41: 4 | J41: 1
...

Sheet Result
B2: 'Core HTML / CSS'
B3: Name Surname
B4: =T('Core HTMLCSS'!J7:K7) -> 2020-Q2
B5: =CONCATENATE("L ", 'Core HTMLCSS'!J8) -> L 1 | C5: =CONCATENATE("L ", 'Core HTMLCSS'!K8) -> L 2
B6: =IF(B7>='Core HTMLCSS'!$H$4,1,0) -> 1 | C6: =IF(C7>='Core HTMLCSS'!$H$4,1,0) -> 0
B7: ='Core HTMLCSS'!J4 -> 0.95797721 | C7: ='Core HTMLCSS'!K4 -> 0
